Workbook

Sheet Best_Trusts
A1: RBK | B1: WALSALL HEALTHCARE NHS TRUST | F1: Walsall
A2: RCF | B2: AIREDALE NHS FOUNDATION TRUST | F2: Airedale
A3: REM | B3: AINTREE UNIVERSITY HOSPITAL NHS FOUNDATION TRUST | F3: Aintree
A4: RGR | B4: WEST SUFFOLK NHS FOUNDATION TRUST | F4: West Suffolk
A5: RJC | B5: SOUTH WARWICKSHIRE NHS FOUNDATION TRUST | F5: South Warwickshire
A6: RLT | B6: GEORGE ELIOT HOSPITAL NHS TRUST | F6: George Eliot
A7: RTE | B7: GLOUCESTERSHIRE HOSPITALS NHS FOUNDATION TRUST | F7: Gloucestershire

Sheet Figure 1
A1: month | B1: org_code | C1: perc_patients_delayed | D1: patients_discharged_volume | E1: perc_bed_delays
A2: Apr-24 | B2: National | C2: 13.538357 | D2: 300908 | E2: 10.084921
A3: May-24 | B3: National | C3: 13.17079 | D3: 328363 | E3: 9.6475574
A4: Jun-24 | B4: National | C4: 13.261209 | D4: 317324 | E4: 9.5856158
A5: Jul-24 | B5: National | C5: 13.482257 | D5: 338697 | E5: 10.374184
A6: Aug-24 | B6: National | C6: 13.06975 | D6: 336288 | E6: 9.667594
A7: Sep-24 | B7: National | C7: 13.157919 | D7: 328137 | E7: 10.180241
A8: Oct-24 | B8: National | C8: 13.623155 | D8: 349985 | E8: 10.618011
A9: Nov-24 | B9: National | C9: 13.370487 | D9: 357616 | E9: 10.5456
A10: Dec-24 | B10: National | C10: 13.551538 | D10: 347931 | E10: 10.095256
A11: Jan-25 | B11: National | C11: 14.47342 | D11: 354201 | E11: 10.809946
A12: Feb-25 | B12: National | C12: 13.97151 | D12: 324811 | E12: 10.747639
A13: Mar-25 | B13: National | C13: 13.730065 | D13: 351455 | E13: 10.646587
... A19: Sep-25 | B19: National | C19: 14.311776 | D19: 324502 | E19: 11.203131
A21: Jul-Sep 2024 | C21: =AVERAGE(C5:C7) -> 13.236642 | D21: =AVERAGE(D5:D7) -> 334374 | E21: =AVERAGE(E5:E7) -> 10.074006
A22: Jul-Sep 2025 | C22: =AVERAGE(C17:C19) -> 14.281592 | D22: =AVERAGE(D17:D19) -> 336802.67 | E22: =AVERAGE(E17:E19) -> 10.984967
C24: =(C22-C21)/C21 -> 0.078943773 | D24: =(D22-D21)/D21 -> 0.0072633239 | E24: =(E22-E21)/E21 -> 0.090426841

Sheet National Delay length
A1: month | B1: org_code | C1: average_delay_los_minus_0_day_delay
A2: Apr-24 | B2: National | C2: 6.1732535
A3: May-24 | B3: National | C3: 5.9697558
A4: Jun-24 | B4: National | C4: 5.9339607
A5: Jul-24 | B5: National | C5: 6.1635424
A6: Aug-24 | B6: National | C6: 6.0442756
A7: Sep-24 | B7: National | C7: 6.3068835
A8: Oct-24 | B8: National | C8: 6.0855723
A9: Nov-24 | B9: National | C9: 6.0615706
A10: Dec-24 | B10: National | C10: 6.0230541
A11: Jan-25 | B11: National | C11: 6.0566078
A12: Feb-25 | B12: National | C12: 6.0884952
A13: Mar-25 | B13: National | C13: 6.2134287
... A19: Sep-25 | B19: National | C19: 6.3030447
A21: Jul-Sep 2024 | C21: =AVERAGE(C5:C7) -> 6.1715671
A22: Jul-Sep 2025 | C22: =AVERAGE(C17:C19) -> 6.0826692
C24: =(C22-C21)/C21 -> -0.014404434

Sheet Figure 2
A1: org_code | B1: post | C1: pre | D1: difference | E1: pre_median | F1: post_median | G1: median_difference | H1: pre_mean | I1: post_mean | J1: mean_difference
A2: RFF | B2: 45.290135 | C2: 34.627996 | D2: 10.66214 | E2: 9.4488423 | F2: 9.9257796 | G2: 0.48841046 | H2: 10.335878 | I2: 10.891988 | J2: 0.55611
A3: RNN | B3: 14.872784 | C3: 5.4767335 | D3: 9.3960503 | E3: 9.4488423 | F3: 9.9257796 | G3: 0.48841046 | H3: 10.335878 | I3: 10.891988 | J3: 0.55611
A4: RRK | B4: 12.136864 | C4: 4.4203078 | D4: 7.7165566 | E4: 9.4488423 | F4: 9.9257796 | G4: 0.48841046 | H4: 10.335878 | I4: 10.891988 | J4: 0.55611
A5: RNZ | B5: 37.20738 | C5: 29.833544 | D5: 7.3738364 | E5: 9.4488423 | F5: 9.9257796 | G5: 0.48841046 | H5: 10.335878 | I5: 10.891988 | J5: 0.55611
A6: RPA | B6: 18.82362 | C6: 12.783679 | D6: 6.0399411 | E6: 9.4488423 | F6: 9.9257796 | G6: 0.48841046 | H6: 10.335878 | I6: 10.891988 | J6: 0.55611
A7: RJZ | B7: 9.2450375 | C7: 4.0443532 | D7: 5.2006843 | E7: 9.4488423 | F7: 9.9257796 | G7: 0.48841046 | H7: 10.335878 | I7: 10.891988 | J7: 0.55611
A8: RJ6 | B8: 8.4477059 | C8: 3.5026997 | D8: 4.9450062 | E8: 9.4488423 | F8: 9.9257796 | G8: 0.48841046 | H8: 10.335878 | I8: 10.891988 | J8: 0.55611
A9: RC9 | B9: 11.478084 | C9: 6.6475779 | D9: 4.8305064 | E9: 9.4488423 | F9: 9.9257796 | G9: 0.48841046 | H9: 10.335878 | I9: 10.891988 | J9: 0.55611
A10: RN5 | B10: 17.274085 | C10: 12.588141 | D10: 4.6859439 | E10: 9.4488423 | F10: 9.9257796 | G10: 0.48841046 | H10: 10.335878 | I10: 10.891988 | J10: 0.55611
A11: RTP | B11: 24.783913 | C11: 20.292478 | D11: 4.4914359 | E11: 9.4488423 | F11: 9.9257796 | G11: 0.48841046 | H11: 10.335878 | I11: 10.891988 | J11: 0.55611
A12: RTF | B12: 7.5162313 | C12: 3.4415492 | D12: 4.0746821 | E12: 9.4488423 | F12: 9.9257796 | G12: 0.48841046 | H12: 10.335878 | I12: 10.891988 | J12: 0.55611
A13: RA7 | B13: 13.955835 | C13: 10.066906 | D13: 3.8889286 | E13: 9.4488423 | F13: 9.9257796 | G13: 0.48841046 | H13: 10.335878 | I13: 10.891988 | J13: 0.55611
... A108: RNS | B108: 1.6879749 | C108: 19.285365 | D108: -17.59739 | E108: 9.4488423 | F108: 9.9257796 | G108: 0.48841046 | H108: 10.335878 | I108: 10.891988 | J108: 0.55611
A110: =COUNTA(A107,A103:A105,A2:A100) -> 103

Sheet Figure 3
A1: org_code | B1: post | C1: pre | D1: difference | E1: pre_median | F1: post_median | G1: median_difference | H1: pre_mean | I1: post_mean | J1: mean_difference | K1: rank_pre | L1: rank_post | M1: rank_change
A2: RTD | B2: 4.2745348 | C2: 2.3475605 | D2: 1.9269743 | E2: 9.4488423 | F2: 9.9257796 | G2: 0.48841046 | H2: 10.335878 | I2: 10.891988 | J2: 0.55611 | K2: 1 | L2: 10 | M2: 76
A3: R1H | B3: 5.9220224 | C3: 2.5905088 | D3: 3.3315135 | E3: 9.4488423 | F3: 9.9257796 | G3: 0.48841046 | H3: 10.335878 | I3: 10.891988 | J3: 0.55611 | K3: 2 | L3: 18 | M3: 90
A4: RP5 | B4: 3.6923304 | C4: 2.9678592 | D4: 0.72447122 | E4: 9.4488423 | F4: 9.9257796 | G4: 0.48841046 | H4: 10.335878 | I4: 10.891988 | J4: 0.55611 | K4: 3 | L4: 6 | M4: 57
A5: RTF | B5: 7.5162313 | C5: 3.4415492 | D5: 4.0746821 | E5: 9.4488423 | F5: 9.9257796 | G5: 0.48841046 | H5: 10.335878 | I5: 10.891988 | J5: 0.55611 | K5: 4 | L5: 31 | M5: 97
A6: RAL | B6: 3.3315231 | C6: 3.4579257 | D6: -0.12640256 | E6: 9.4488423 | F6: 9.9257796 | G6: 0.48841046 | H6: 10.335878 | I6: 10.891988 | J6: 0.55611 | K6: 5 | L6: 5 | M6: 40
A7: RJ6 | B7: 8.4477059 | C7: 3.5026997 | D7: 4.9450062 | E7: 9.4488423 | F7: 9.9257796 | G7: 0.48841046 | H7: 10.335878 | I7: 10.891988 | J7: 0.55611 | K7: 6 | L7: 37 | M7: 101
A8: RXW | B8: 2.9146481 | C8: 3.9563023 | D8: -1.0416543 | E8: 9.4488423 | F8: 9.9257796 | G8: 0.48841046 | H8: 10.335878 | I8: 10.891988 | J8: 0.55611 | K8: 7 | L8: 3 | M8: 24
A9: RJZ | B9: 9.2450375 | C9: 4.0443532 | D9: 5.2006843 | E9: 9.4488423 | F9: 9.9257796 | G9: 0.48841046 | H9: 10.335878 | I9: 10.891988 | J9: 0.55611 | K9: 8 | L9: 47 | M9: 102
A10: RJE | B10: 4.6152074 | C10: 4.1560243 | D10: 0.45918303 | E10: 9.4488423 | F10: 9.9257796 | G10: 0.48841046 | H10: 10.335878 | I10: 10.891988 | J10: 0.55611 | K10: 9 | L10: 12 | M10: 51
A11: RJ1 | B11: 7.0341733 | C11: 4.2569444 | D11: 2.7772289 | E11: 9.4488423 | F11: 9.9257796 | G11: 0.48841046 | H11: 10.335878 | I11: 10.891988 | J11: 0.55611 | K11: 10 | L11: 28 | M11: 85
A12: RAJ | B12: 5.9198755 | C12: 4.3098632 | D12: 1.6100123 | E12: 9.4488423 | F12: 9.9257796 | G12: 0.48841046 | H12: 10.335878 | I12: 10.891988 | J12: 0.55611 | K12: 11 | L12: 17 | M12: 69
A13: RRK | B13: 12.136864 | C13: 4.4203078 | D13: 7.7165566 | E13: 9.4488423 | F13: 9.9257796 | G13: 0.48841046 | H13: 10.335878 | I13: 10.891988 | J13: 0.55611 | K13: 12 | L13: 72 | M13: 105
... A108: RFF | B108: 45.290135 | C108: 34.627996 | D108: 10.66214 | E108: 9.4488423 | F108: 9.9257796 | G108: 0.48841046 | H108: 10.335878 | I108: 10.891988 | J108: 0.55611 | K108: 107 | L108: 107 | M108: 107
B110: RTD | C110: R1H | D110: RP5 | E110: RTF | F110: RAL | G110: RJ6 | H110: RXW | I110: RJZ | J110: RJE | K110: RJ1 | L110: RAJ | M110: RRK | N110: RF4 | O110: RRV | P110: RWF | Q110: RNA | R110: RWE | S110: RX1 | T110: RNN | U110: RCD | V110: RWG | W110: RMP | X110: RAS | Y110: RCB | Z110: RQX | AA110: RDU | AB110: RDE | AC110: RFS | AD110: RXP | AE110: RA9 | AF110: RC9 | AG110: RTR | AH110: RWA | AI110: RBK | AJ110: RA2 | AK110: RXN | AL110: RWH | AM110: RL4 | AN110: RJ7 | AO110: RK9 | AP110: RQM | AQ110: RVW | AR110: RJL | AS110: RN3 | AT110: RJ2 | AU110: R0A | AV110: RBN | AW110: RK5 | AX110: REF | AY110: RD1 | AZ110: RH8 | BA110: RTH | BB110: RFR | BC110: R0B | BD110: RHQ | BE110: RM1 | BF110: RBD | BG110: RN7 | BH110: RA7 | BI110: RGT | BJ110: RWD | BK110: RAE | BL110: RHW | BM110: RR8 | BN110: RKB | BO110: RTG | BP110: RYJ | BQ110: RTK | BR110: RWJ | BS110: RWP | BT110: RM3 | BU110: RD8 | BV110: RJC | BW110: RXK | BX110: RXF | BY110: RKE | BZ110: RN5 | CA110: RPA | CB110: RHU | CC110: RXQ | CD110: RNQ | CE110: REM | CF110: RLQ | CG110: RWW | CH110: RHM | CI110: RTE | CJ110: RVJ | CK110: R0D | CL110: RGP | CM110: RWY | CN110: RCF | CO110: RYR | CP110: R1F | CQ110: RVR | CR110: RJR | CS110: RTX | CT110: RVV | CU110: RAX | CV110: RH5 | CW110: RR7 | CX110: RGR | CY110: RNS | CZ110: RXC | DA110: RTP | DB110: RLT | DC110: RNZ | DD110: RFF
A111: Jul-Sep 2025 | B111: 4.2745348 | C111: 5.9220224 | D111: 3.6923304 | E111: 7.5162313 | F111: 3.3315231 | G111: 8.4477059 | H111: 2.9146481 | I111: 9.2450375 | J111: 4.6152074 | K111: 7.0341733 | L111: 5.9198755 | M111: 12.136864 | N111: 6.1759868 | O111: 3.9011456 | P111: 2.6097433 | Q111: 6.3209264 | R111: 5.4069395 | S111: 6.7625187 | T111: 14.872784 | U111: 6.157391 | V111: 4.0073972 | W111: 5.1091366 | X111: 9.6408456 | Y111: 6.1280518 | Z111: 9.1460608 | AA111: 5.2511927 | AB111: 4.5896707 | AC111: 6.447568 | AD111: 5.7999475 | AE111: 6.4273283 | AF111: 11.478084 | AG111: 7.8370628 | AH111: 7.2046432 | AI111: 4.0947737 | AJ111: 10.190566 | AK111: 8.9986504 | AL111: 8.1532398 | AM111: 7.6606282 | AN111: 6.7206554 | AO111: 8.6439779 | AP111: 10.175635 | AQ111: 9.4568514 | AR111: 9.3924731 | AS111: 12.333282 | AT111: 8.7736567 | AU111: 8.2993564 | AV111: 6.2649218 | AW111: 10.304038 | AX111: 7.3526198 | AY111: 8.405767 | AZ111: 10.760376 | BA111: 11.05282 | BB111: 10.097482 | BC111: 9.9257796 | BD111: 9.7100107 | BE111: 9.3101304 | BF111: 13.284701 | BG111: 12.5558 | BH111: 13.955835 | BI111: 12.645795 | BJ111: 11.965233 | BK111: 13.744434 | BL111: 13.059375 | BM111: 11.117797 | BN111: 11.065266 | BO111: 11.494671 | BP111: 10.57803 | BQ111: 8.7970032 | BR111: 9.424315 | BS111: 10.052227 | BT111: 8.9656983 | BU111: 12.879507 | BV111: 3.1873123 | BW111: 11.759998 | BX111: 11.346907 | BY111: 12.675364 | BZ111: 17.274085 | CA111: 18.82362 | CB111: 16.263568 | CC111: 13.704337 | CD111: 12.384575 | CE111: 11.085096 | CF111: 12.484777 | CG111: 15.305669 | CH111: 16.356419 | CI111: 11.486529 | CJ111: 14.401856 | CK111: 14.564853 | CL111: 14.419355 | CM111: 13.705164 | CN111: 9.1447174 | CO111: 17.477388 | CP111: 17.319555 | CQ111: 13.51052 | CR111: 13.924159 | CS111: 19.283962 | CT111: 15.960756 | CU111: 8.9693155 | CV111: 20.23775 | CW111: 18.252442 | CX111: 8.9188284 | CY111: 1.6879749 | CZ111: 23.410435 | DA111: 24.783913 | DB111: 20.84604 | DC111: 37.20738 | DD111: 45.290135
A112: Jul-Sep 2024 | B112: 2.3475605 | C112: 2.5905088 | D112: 2.9678592 | E112: 3.4415492 | F112: 3.4579257 | G112: 3.5026997 | H112: 3.9563023 | I112: 4.0443532 | J112: 4.1560243 | K112: 4.2569444 | L112: 4.3098632 | M112: 4.4203078 | N112: 4.4972191 | O112: 4.5815601 | P112: 4.7410035 | Q112: 5.2279174 | R112: 5.3454086 | S112: 5.4136218 | T112: 5.4767335 | U112: 5.6689805 | V112: 5.6712846 | W112: 5.8984777 | X112: 5.9189382 | Y112: 5.9845855 | Z112: 6.078312 | AA112: 6.2550216 | AB112: 6.3015956 | AC112: 6.3122515 | AD112: 6.3533585 | AE112: 6.6276137 | AF112: 6.6475779 | AG112: 6.8177425 | AH112: 6.9097817 | AI112: 7.0073698 | AJ112: 7.0330601 | AK112: 7.0676523 | AL112: 7.2216559 | AM112: 7.6451095 | AN112: 7.6587055 | AO112: 7.9274597 | AP112: 8.0553559 | AQ112: 8.29643 | AR112: 8.4259484 | AS112: 8.5209228 | AT112: 8.5638286 | AU112: 8.581427 | AV112: 8.6322617 | AW112: 8.6884049 | AX112: 8.8121143 | AY112: 8.8206579 | AZ112: 9.1088351 | BA112: 9.2857304 | BB112: 9.3645023 | BC112: 9.4488423 | BD112: 9.6001901 | BE112: 9.7250456 | BF112: 9.7772895 | BG112: 9.9977974 | BH112: 10.066906 | BI112: 10.0889 | BJ112: 10.106411 | BK112: 10.214763 | BL112: 10.243317 | BM112: 10.485881 | BN112: 10.586492 | BO112: 10.758388 | BP112: 10.759933 | BQ112: 10.781113 | BR112: 10.950542 | BS112: 10.98702 | BT112: 10.989393 | BU112: 11.012033 | BV112: 11.350545 | BW112: 11.428622 | BX112: 11.523168 | BY112: 11.808457 | BZ112: 12.588141 | CA112: 12.783679 | CB112: 13.054695 | CC112: 13.570387 | CD112: 13.674047 | CE112: 13.678414 | CF112: 13.871966 | CG112: 14.182223 | CH112: 14.28156 | CI112: 14.332633 | CJ112: 14.604966 | CK112: 14.789187 | CL112: 14.846457 | CM112: 14.965829 | CN112: 14.978526 | CO112: 15.171593 | CP112: 16.1329 | CQ112: 16.490677 | CR112: 17.154591 | CS112: 17.308873 | CT112: 17.486158 | CU112: 17.513769 | CV112: 18.166441 | CW112: 18.240942 | CX112: 18.837651 | CY112: 19.285365 | CZ112: 20.049818 | DA112: 20.292478 | DB112: 25.554073 | DC112: 29.833544 | DD112: 34.627996

Sheet Figure 4
A1: org_code | B1: Pre_occupancy | C1: Post_occupancy | D1: Pre_beds | E1: Post_beds | F1: All_Median_Pre_occupancy | G1: All_Median_Post_occupancy | H1: All_Median_Pre_beds | I1: All_Median_Post_beds | J1: avgbest_Pre_occupancy | K1: avgbest_Post_occupancy | L1: avgbest_Pre_beds | M1: avgbest_Post_beds | N1: occupancy_change_best_trusts | O1: occupancy_change_all_trusts | P1: beds_change_best_trusts | Q1: beds_change_all_trusts
A2: RBK | B2: 0.92933333 | C2: 0.93533333 | D2: 534 | E2: 516 | F2: 0.933 | G2: 0.93 | H2: 736.5 | I2: 730 | J2: 0.9282381 | K2: 0.93266667 | L2: 652.71429 | M2: 642.28571 | N2: 0.006 | O2: -0.003 | P2: -0.033707865 | Q2: -0.0088255261
A3: RCF | B3: 0.945 | C3: 0.939 | D3: 343 | E3: 363.33333 | F3: 0.933 | G3: 0.93 | H3: 736.5 | I3: 730 | J3: 0.9282381 | K3: 0.93266667 | L3: 652.71429 | M3: 642.28571 | N3: -0.006 | O3: -0.003 | P3: 0.059280855 | Q3: -0.0088255261
A4: REM | B4: 0.93266667 | C4: 0.953 | D4: 1599.3333 | E4: 1506.3333 | F4: 0.933 | G4: 0.93 | H4: 736.5 | I4: 730 | J4: 0.9282381 | K4: 0.93266667 | L4: 652.71429 | M4: 642.28571 | N4: 0.020333333 | O4: -0.003 | P4: -0.058149229 | Q4: -0.0088255261
A5: RGR | B5: 0.91933333 | C5: 0.92033333 | D5: 447 | E5: 449.33333 | F5: 0.933 | G5: 0.93 | H5: 736.5 | I5: 730 | J5: 0.9282381 | K5: 0.93266667 | L5: 652.71429 | M5: 642.28571 | N5: 0.001 | O5: -0.003 | P5: 0.0052199851 | Q5: -0.0088255261
A6: RJC | B6: 0.91233333 | C6: 0.94866667 | D6: 410.66667 | E6: 419 | F6: 0.933 | G6: 0.93 | H6: 736.5 | I6: 730 | J6: 0.9282381 | K6: 0.93266667 | L6: 652.71429 | M6: 642.28571 | N6: 0.036333333 | O6: -0.003 | P6: 0.020292208 | Q6: -0.0088255261
A7: RLT | B7: 0.97766667 | C7: 0.95166667 | D7: 370.66667 | E7: 384.33333 | F7: 0.933 | G7: 0.93 | H7: 736.5 | I7: 730 | J7: 0.9282381 | K7: 0.93266667 | L7: 652.71429 | M7: 642.28571 | N7: -0.026 | O7: -0.003 | P7: 0.036870504 | Q7: -0.0088255261
A8: RTE | B8: 0.88133333 | C8: 0.88066667 | D8: 864.33333 | E8: 857.66667 | F8: 0.933 | G8: 0.93 | H8: 736.5 | I8: 730 | J8: 0.9282381 | K8: 0.93266667 | L8: 652.71429 | M8: 642.28571 | N8: -0.00066666667 | O8: -0.003 | P8: -0.0077130737 | Q8: -0.0088255261
A10: org_code | C10: Time period | D10: Occupancy rate
A11: RTE | B11: =VLOOKUP(A11,Best_Trusts!$A$1:$F$7,6,FALSE) -> Gloucestershire | C11: Jul-Sep 2024 | D11: 0.88133333
A12: RJC | B12: =VLOOKUP(A12,Best_Trusts!$A$1:$F$7,6,FALSE) -> South Warwickshire | C12: Jul-Sep 2024 | D12: 0.91233333
A13: RGR | B13: =VLOOKUP(A13,Best_Trusts!$A$1:$F$7,6,FALSE) -> West Suffolk | C13: Jul-Sep 2024 | D13: 0.91933333
A14: RBK | B14: =VLOOKUP(A14,Best_Trusts!$A$1:$F$7,6,FALSE) -> Walsall | C14: Jul-Sep 2024 | D14: 0.92933333
A15: REM | B15: =VLOOKUP(A15,Best_Trusts!$A$1:$F$7,6,FALSE) -> Aintree | C15: Jul-Sep 2024 | D15: 0.93266667
A16: RCF | B16: =VLOOKUP(A16,Best_Trusts!$A$1:$F$7,6,FALSE) -> Airedale | C16: Jul-Sep 2024 | D16: 0.945
A17: RLT | B17: =VLOOKUP(A17,Best_Trusts!$A$1:$F$7,6,FALSE) -> George Eliot | C17: Jul-Sep 2024 | D17: 0.97766667
A18: Average* | B18: Average* | C18: Jul-Sep 2024 | D18: 0.9282381
A19: Average* | B19: Average* | C19: Jul-Sep 2025 | D19: 0.93266667
A20: RTE | B20: =VLOOKUP(A20,Best_Trusts!$A$1:$F$7,6,FALSE) -> Gloucestershire | C20: Jul-Sep 2025 | D20: =VLOOKUP(A20,$A$2:$C$8,3,FALSE) -> 0.88066667
A21: RJC | B21: =VLOOKUP(A21,Best_Trusts!$A$1:$F$7,6,FALSE) -> South Warwickshire | C21: Jul-Sep 2025 | D21: =VLOOKUP(A21,$A$2:$C$8,3,FALSE) -> 0.94866667
A22: RGR | B22: =VLOOKUP(A22,Best_Trusts!$A$1:$F$7,6,FALSE) -> West Suffolk | C22: Jul-Sep 2025 | D22: =VLOOKUP(A22,$A$2:$C$8,3,FALSE) -> 0.92033333
A23: RBK | B23: =VLOOKUP(A23,Best_Trusts!$A$1:$F$7,6,FALSE) -> Walsall | C23: Jul-Sep 2025 | D23: =VLOOKUP(A23,$A$2:$C$8,3,FALSE) -> 0.93533333
A24: REM | B24: =VLOOKUP(A24,Best_Trusts!$A$1:$F$7,6,FALSE) -> Aintree | C24: Jul-Sep 2025 | D24: =VLOOKUP(A24,$A$2:$C$8,3,FALSE) -> 0.953
A25: RCF | B25: =VLOOKUP(A25,Best_Trusts!$A$1:$F$7,6,FALSE) -> Airedale | C25: Jul-Sep 2025 | D25: =VLOOKUP(A25,$A$2:$C$8,3,FALSE) -> 0.939
A26: RLT | B26: =VLOOKUP(A26,Best_Trusts!$A$1:$F$7,6,FALSE) -> George Eliot | C26: Jul-Sep 2025 | D26: =VLOOKUP(A26,$A$2:$C$8,3,FALSE) -> 0.95166667
A28: National median | B28: Jul-Sep 2024 | C28: 0.933
A29: National median | B29: Jul-Sep 2025 | C29: 0.93

Sheet Figure 4b
A1: org_code | B1: Pre_beds | C1: Post_beds | D1: difference | E1: pct_difference | F1: All_Median_Pre_beds | G1: All_Median_Post_beds | H1: avgbest_Pre_beds | I1: avgbest_Post_beds
A2: RBK | B2: 534 | C2: 516 | D2: -18 | E2: -0.033707865 | F2: 736.5 | G2: 730 | H2: 652.71429 | I2: 642.28571
A3: RCF | B3: 343 | C3: 363.33333 | D3: 20.333333 | E3: 0.059280855 | F3: 736.5 | G3: 730 | H3: 652.71429 | I3: 642.28571
A4: REM | B4: 1599.3333 | C4: 1506.3333 | D4: -93 | E4: -0.058149229 | F4: 736.5 | G4: 730 | H4: 652.71429 | I4: 642.28571
A5: RGR | B5: 447 | C5: 449.33333 | D5: 2.3333333 | E5: 0.0052199851 | F5: 736.5 | G5: 730 | H5: 652.71429 | I5: 642.28571
A6: RJC | B6: 410.66667 | C6: 419 | D6: 8.3333333 | E6: 0.020292208 | F6: 736.5 | G6: 730 | H6: 652.71429 | I6: 642.28571
A7: RLT | B7: 370.66667 | C7: 384.33333 | D7: 13.666667 | E7: 0.036870504 | F7: 736.5 | G7: 730 | H7: 652.71429 | I7: 642.28571
A8: RTE | B8: 864.33333 | C8: 857.66667 | D8: -6.6666667 | E8: -0.0077130737 | F8: 736.5 | G8: 730 | H8: 652.71429 | I8: 642.28571

Sheet Figure 5
A1: org_code | B1: Pre_doctors | C1: Pre_nurses | D1: Post_doctors | E1: Post_nurses | F1: All_Median_Pre_nurses | G1: All_Median_Pre_doctors | H1: All_Median_Post_nurses | I1: All_Median_Post_doctors | J1: avgbest_Pre_nurses | K1: avgbest_Post_nurses | L1: avgbest_Pre_doctors | M1: avgbest_Post_doctors | N1: doc_change_best_trusts | O1: nurse_change_best_trusts | P1: doc_change_all_trusts | Q1: nurse_change_all_trusts
A2: RBK | B2: 532.51549 | C2: 1354.4435 | D2: 546.77416 | E2: 1404.9934 | F2: 1889.4665 | G2: 826.77589 | H2: 1883.5244 | I2: 870.21669 | J2: 1612.0159 | K2: 1656.1635 | L2: 702.70999 | M2: 741.41657 | N2: 0.02677606 | O2: 0.037321475 | P2: 0.052542419 | Q2: -0.0031448559
A3: RCF | B3: 343.71009 | C3: 746.43832 | D3: 369.27856 | E3: 787.18661 | F3: 1889.4665 | G3: 826.77589 | H3: 1883.5244 | I3: 870.21669 | J3: 1612.0159 | K3: 1656.1635 | L3: 702.70999 | M3: 741.41657 | N3: 0.074389631 | O3: 0.054590293 | P3: 0.052542419 | Q3: -0.0031448559
A4: REM | B4: 1680.1466 | C4: 3728.7086 | D4: 1755.2429 | E4: 3762.6353 | F4: 1889.4665 | G4: 826.77589 | H4: 1883.5244 | I4: 870.21669 | J4: 1612.0159 | K4: 1656.1635 | L4: 702.70999 | M4: 741.41657 | N4: 0.044696285 | O4: 0.0090987785 | P4: 0.052542419 | Q4: -0.0031448559
A5: RGR | B5: 533.08225 | C5: 1153.1382 | D5: 532.26872 | E5: 1154.6658 | F5: 1889.4665 | G5: 826.77589 | H5: 1883.5244 | I5: 870.21669 | J5: 1612.0159 | K5: 1656.1635 | L5: 702.70999 | M5: 741.41657 | N5: -0.001526081 | O5: 0.0013247935 | P5: 0.052542419 | Q5: -0.0031448559
A6: RJC | B6: 462.04148 | C6: 1488.2754 | D6: 518.50705 | E6: 1599.5047 | F6: 1889.4665 | G6: 826.77589 | H6: 1883.5244 | I6: 870.21669 | J6: 1612.0159 | K6: 1656.1635 | L6: 702.70999 | M6: 741.41657 | N6: 0.12220887 | O6: 0.074737047 | P6: 0.052542419 | Q6: -0.0031448559
A7: RLT | B7: 374.00483 | C7: 687.71201 | D7: 425.29692 | E7: 743.21465 | F7: 1889.4665 | G7: 826.77589 | H7: 1883.5244 | I7: 870.21669 | J7: 1612.0159 | K7: 1656.1635 | L7: 702.70999 | M7: 741.41657 | N7: 0.13714284 | O7: 0.08070623 | P7: 0.052542419 | Q7: -0.0031448559
A8: RTE | B8: 993.46919 | C8: 2125.395 | D8: 1042.5477 | E8: 2140.9442 | F8: 1889.4665 | G8: 826.77589 | H8: 1883.5244 | I8: 870.21669 | J8: 1612.0159 | K8: 1656.1635 | L8: 702.70999 | M8: 741.41657 | N8: 0.049401113 | O8: 0.007315928 | P8: 0.052542419 | Q8: -0.0031448559
A10: Staff volumes | F10: Staff % change | K10: Combined staff | O10: Flourish copy
A11: org_code | B11: Time period | C11: Doctors | D11: Nurses | F11: org_code | G11: Time period | H11: Doctors % | I11: Nurses % | K11: org_code | L11: Time period | M11: Total staff | O11: Trust | P11: Time period | Q11: Type | R11: Combined staff | S11: Each staff | T11: Change in doctors (%) | U11: Change in nurses(%)
A12: RBK | B12: May-Jul 2024 | C12: 532.51549 | D12: 1354.4435 | F12: RBK | G12: 2024 vs 2025 | H12: =(D2-B2)/B2 -> 0.02677606 | I12: =(E2-C2)/C2 -> 0.037321475 | K12: RBK | L12: May-Jul 2025 | M12: =SUM(D2:E2) -> 1951.7675 | O12: RBK | P12: May-Jul 2024 | Q12: Doctors | R12: =VLOOKUP(O12,$K$12:$M$20,3,FALSE) -> 1951.7675 | S12: =VLOOKUP(O12,$A$12:$D$20,3,FALSE) -> 532.51549 | T12: =VLOOKUP(O12,$F$12:$I$20,3,FALSE) -> 0.02677606 | U12: =VLOOKUP(O12,$F$12:$I$20,4,FALSE) -> 0.037321475
A13: RCF | B13: May-Jul 2024 | C13: 343.71009 | D13: 746.43832 | F13: RCF | G13: 2024 vs 2025 | H13: =(D3-B3)/B3 -> 0.074389631 | I13: =(E3-C3)/C3 -> 0.054590293 | K13: RCF | L13: May-Jul 2025 | M13: =SUM(D3:E3) -> 1156.4652 | O13: RCF | P13: May-Jul 2024 | Q13: Doctors | R13: =VLOOKUP(O13,$K$12:$M$20,3,FALSE) -> 1156.4652 | S13: =VLOOKUP(O13,$A$12:$D$20,3,FALSE) -> 343.71009 | T13: =VLOOKUP(O13,$F$12:$I$20,3,FALSE) -> 0.074389631 | U13: =VLOOKUP(O13,$F$12:$I$20,4,FALSE) -> 0.054590293
A14: REM | B14: May-Jul 2024 | C14: 1680.1466 | D14: 3728.7086 | F14: REM | G14: 2024 vs 2025 | H14: =(D4-B4)/B4 -> 0.044696285 | I14: =(E4-C4)/C4 -> 0.0090987785 | K14: REM | L14: May-Jul 2025 | M14: =SUM(D4:E4) -> 5517.8782 | O14: REM | P14: May-Jul 2024 | Q14: Doctors | R14: =VLOOKUP(O14,$K$12:$M$20,3,FALSE) -> 5517.8782 | S14: =VLOOKUP(O14,$A$12:$D$20,3,FALSE) -> 1680.1466 | T14: =VLOOKUP(O14,$F$12:$I$20,3,FALSE) -> 0.044696285 | U14: =VLOOKUP(O14,$F$12:$I$20,4,FALSE) -> 0.0090987785
A15: RGR | B15: May-Jul 2024 | C15: 533.08225 | D15: 1153.1382 | F15: RGR | G15: 2024 vs 2025 | H15: =(D5-B5)/B5 -> -0.001526081 | I15: =(E5-C5)/C5 -> 0.0013247935 | K15: RGR | L15: May-Jul 2025 | M15: =SUM(D5:E5) -> 1686.9346 | O15: RGR | P15: May-Jul 2024 | Q15: Doctors | R15: =VLOOKUP(O15,$K$12:$M$20,3,FALSE) -> 1686.9346 | S15: =VLOOKUP(O15,$A$12:$D$20,3,FALSE) -> 533.08225 | T15: =VLOOKUP(O15,$F$12:$I$20,3,FALSE) -> -0.001526081 | U15: =VLOOKUP(O15,$F$12:$I$20,4,FALSE) -> 0.0013247935
A16: RJC | B16: May-Jul 2024 | C16: 462.04148 | D16: 1488.2754 | F16: RJC | G16: 2024 vs 2025 | H16: =(D6-B6)/B6 -> 0.12220887 | I16: =(E6-C6)/C6 -> 0.074737047 | K16: RJC | L16: May-Jul 2025 | M16: =SUM(D6:E6) -> 2118.0118 | O16: RJC | P16: May-Jul 2024 | Q16: Doctors | R16: =VLOOKUP(O16,$K$12:$M$20,3,FALSE) -> 2118.0118 | S16: =VLOOKUP(O16,$A$12:$D$20,3,FALSE) -> 462.04148 | T16: =VLOOKUP(O16,$F$12:$I$20,3,FALSE) -> 0.12220887 | U16: =VLOOKUP(O16,$F$12:$I$20,4,FALSE) -> 0.074737047
A17: RLT | B17: May-Jul 2024 | C17: 374.00483 | D17: 687.71201 | F17: RLT | G17: 2024 vs 2025 | H17: =(D7-B7)/B7 -> 0.13714284 | I17: =(E7-C7)/C7 -> 0.08070623 | K17: RLT | L17: May-Jul 2025 | M17: =SUM(D7:E7) -> 1168.5116 | O17: RLT | P17: May-Jul 2024 | Q17: Doctors | R17: =VLOOKUP(O17,$K$12:$M$20,3,FALSE) -> 1168.5116 | S17: =VLOOKUP(O17,$A$12:$D$20,3,FALSE) -> 374.00483 | T17: =VLOOKUP(O17,$F$12:$I$20,3,FALSE) -> 0.13714284 | U17: =VLOOKUP(O17,$F$12:$I$20,4,FALSE) -> 0.08070623
A18: RTE | B18: May-Jul 2024 | C18: 993.46919 | D18: 2125.395 | F18: RTE | G18: 2024 vs 2025 | H18: =(D8-B8)/B8 -> 0.049401113 | I18: =(E8-C8)/C8 -> 0.007315928 | K18: RTE | L18: May-Jul 2025 | M18: =SUM(D8:E8) -> 3183.4919 | O18: RTE | P18: May-Jul 2024 | Q18: Doctors | R18: =VLOOKUP(O18,$K$12:$M$20,3,FALSE) -> 3183.4919 | S18: =VLOOKUP(O18,$A$12:$D$20,3,FALSE) -> 993.46919 | T18: =VLOOKUP(O18,$F$12:$I$20,3,FALSE) -> 0.049401113 | U18: =VLOOKUP(O18,$F$12:$I$20,4,FALSE) -> 0.007315928
A19: Average* | B19: May-Jul 2024 | C19: 702.70999 | D19: 1612.0159 | F19: Average* | G19: 2024 vs 2025 | H19: =(M2-L2)/L2 -> 0.055081868 | I19: =(K2-J2)/J2 -> 0.027386621 | K19: Average* | L19: May-Jul 2025 | M19: =SUM(M2,K2) -> 2397.5801 | O19: Average* | P19: May-Jul 2024 | Q19: Doctors | R19: =VLOOKUP(O19,$K$12:$M$20,3,FALSE) -> 2397.5801 | S19: =VLOOKUP(O19,$A$12:$D$20,3,FALSE) -> 702.70999 | T19: =VLOOKUP(O19,$F$12:$I$20,3,FALSE) -> 0.055081868 | U19: =VLOOKUP(O19,$F$12:$I$20,4,FALSE) -> 0.027386621
A20: National median | B20: May-Jul 2024 | C20: 826.77589 | D20: 1889.4665 | F20: National median | G20: 2024 vs 2025 | H20: =(I8-G8)/G8 -> 0.052542419 | I20: =(H8-F8)/F8 -> -0.0031448559 | K20: National median | L20: May-Jul 2025 | M20: =SUM(H2:I2) -> 2753.7411 | O20: National median | P20: May-Jul 2024 | Q20: Doctors | R20: =VLOOKUP(O20,$K$12:$M$20,3,FALSE) -> 2753.7411 | S20: =VLOOKUP(O20,$A$12:$D$20,3,FALSE) -> 826.77589 | T20: =VLOOKUP(O20,$F$12:$I$20,3,FALSE) -> 0.052542419 | U20: =VLOOKUP(O20,$F$12:$I$20,4,FALSE) -> -0.0031448559
O21: Average* | P21: May-Jul 2025 | Q21: Doctors | R21: =VLOOKUP(O21,$K$12:$M$20,3,FALSE) -> 2397.5801 | S21: =VLOOKUP(O21,$A$22:$D$30,3,FALSE) -> 741.41657 | T21: =VLOOKUP(O21,$F$12:$I$20,3,FALSE) -> 0.055081868 | U21: =VLOOKUP(O21,$F$12:$I$20,4,FALSE) -> 0.027386621
A22: Average* | B22: May-Jul 2025 | C22: 741.41657 | D22: 1656.1635 | F22: Staff % change | O22: National median | P22: May-Jul 2025 | Q22: Doctors | R22: =VLOOKUP(O22,$K$12:$M$20,3,FALSE) -> 2753.7411 | S22: =VLOOKUP(O22,$A$22:$D$30,3,FALSE) -> 870.21669 | T22: =VLOOKUP(O22,$F$12:$I$20,3,FALSE) -> 0.052542419 | U22: =VLOOKUP(O22,$F$12:$I$20,4,FALSE) -> -0.0031448559
A23: RBK | B23: May-Jul 2025 | C23: 546.77416 | D23: 1404.9934 | F23: org_code | G23: Time period | H23: Doctors % | I23: Nurses % | O23: RBK | P23: May-Jul 2025 | Q23: Doctors | R23: =VLOOKUP(O23,$K$12:$M$20,3,FALSE) -> 1951.7675 | S23: =VLOOKUP(O23,$A$22:$D$30,3,FALSE) -> 546.77416 | T23: =VLOOKUP(O23,$F$12:$I$20,3,FALSE) -> 0.02677606 | U23: =VLOOKUP(O23,$F$12:$I$20,4,FALSE) -> 0.037321475
A24: RCF | B24: May-Jul 2025 | C24: 369.27856 | D24: 787.18661 | F24: RLT | G24: 2024 vs 2025 | H24: 0.13714284 | I24: 0.08070623 | O24: RCF | P24: May-Jul 2025 | Q24: Doctors | R24: =VLOOKUP(O24,$K$12:$M$20,3,FALSE) -> 1156.4652 | S24: =VLOOKUP(O24,$A$22:$D$30,3,FALSE) -> 369.27856 | T24: =VLOOKUP(O24,$F$12:$I$20,3,FALSE) -> 0.074389631 | U24: =VLOOKUP(O24,$F$12:$I$20,4,FALSE) -> 0.054590293
A25: REM | B25: May-Jul 2025 | C25: 1755.2429 | D25: 3762.6353 | F25: RJC | G25: 2024 vs 2025 | H25: 0.12220887 | I25: 0.074737047 | O25: REM | P25: May-Jul 2025 | Q25: Doctors | R25: =VLOOKUP(O25,$K$12:$M$20,3,FALSE) -> 5517.8782 | S25: =VLOOKUP(O25,$A$22:$D$30,3,FALSE) -> 1755.2429 | T25: =VLOOKUP(O25,$F$12:$I$20,3,FALSE) -> 0.044696285 | U25: =VLOOKUP(O25,$F$12:$I$20,4,FALSE) -> 0.0090987785
A26: RGR | B26: May-Jul 2025 | C26: 532.26872 | D26: 1154.6658 | F26: RCF | G26: 2024 vs 2025 | H26: 0.074389631 | I26: 0.054590293 | O26: RGR | P26: May-Jul 2025 | Q26: Doctors | R26: =VLOOKUP(O26,$K$12:$M$20,3,FALSE) -> 1686.9346 | S26: =VLOOKUP(O26,$A$22:$D$30,3,FALSE) -> 532.26872 | T26: =VLOOKUP(O26,$F$12:$I$20,3,FALSE) -> -0.001526081 | U26: =VLOOKUP(O26,$F$12:$I$20,4,FALSE) -> 0.0013247935
A27: RJC | B27: May-Jul 2025 | C27: 518.50705 | D27: 1599.5047 | F27: RTE | G27: 2024 vs 2025 | H27: 0.049401113 | I27: 0.007315928 | O27: RJC | P27: May-Jul 2025 | Q27: Doctors | R27: =VLOOKUP(O27,$K$12:$M$20,3,FALSE) -> 2118.0118 | S27: =VLOOKUP(O27,$A$22:$D$30,3,FALSE) -> 518.50705 | T27: =VLOOKUP(O27,$F$12:$I$20,3,FALSE) -> 0.12220887 | U27: =VLOOKUP(O27,$F$12:$I$20,4,FALSE) -> 0.074737047
A28: RLT | B28: May-Jul 2025 | C28: 425.29692 | D28: 743.21465 | F28: REM | G28: 2024 vs 2025 | H28: 0.044696285 | I28: 0.0090987785 | O28: RLT | P28: May-Jul 2025 | Q28: Doctors | R28: =VLOOKUP(O28,$K$12:$M$20,3,FALSE) -> 1168.5116 | S28: =VLOOKUP(O28,$A$22:$D$30,3,FALSE) -> 425.29692 | T28: =VLOOKUP(O28,$F$12:$I$20,3,FALSE) -> 0.13714284 | U28: =VLOOKUP(O28,$F$12:$I$20,4,FALSE) -> 0.08070623
A29: RTE | B29: May-Jul 2025 | C29: 1042.5477 | D29: 2140.9442 | F29: RBK | G29: 2024 vs 2025 | H29: 0.02677606 | I29: 0.037321475 | O29: RTE | P29: May-Jul 2025 | Q29: Doctors | R29: =VLOOKUP(O29,$K$12:$M$20,3,FALSE) -> 3183.4919 | S29: =VLOOKUP(O29,$A$22:$D$30,3,FALSE) -> 1042.5477 | T29: =VLOOKUP(O29,$F$12:$I$20,3,FALSE) -> 0.049401113 | U29: =VLOOKUP(O29,$F$12:$I$20,4,FALSE) -> 0.007315928
A30: National median | B30: May-Jul 2025 | C30: 870.21669 | D30: 1883.5244 | F30: RGR | G30: 2024 vs 2025 | H30: -0.001526081 | I30: 0.0013247935 | O30: RBK | P30: May-Jul 2024 | Q30: Nurses | R30: =VLOOKUP(O30,$K$12:$M$20,3,FALSE) -> 1951.7675 | S30: =VLOOKUP(O30,$A$12:$D$20,4,FALSE) -> 1354.4435 | T30: =VLOOKUP(O30,$F$12:$I$20,3,FALSE) -> 0.02677606 | U30: =VLOOKUP(O30,$F$12:$I$20,4,FALSE) -> 0.037321475
F31: Average* | G31: 2024 vs 2025 | H31: 0.055081868 | I31: 0.027386621 | O31: RCF | P31: May-Jul 2024 | Q31: Nurses | R31: =VLOOKUP(O31,$K$12:$M$20,3,FALSE) -> 1156.4652 | S31: =VLOOKUP(O31,$A$12:$D$20,4,FALSE) -> 746.43832 | T31: =VLOOKUP(O31,$F$12:$I$20,3,FALSE) -> 0.074389631 | U31: =VLOOKUP(O31,$F$12:$I$20,4,FALSE) -> 0.054590293
F32: National median | G32: 2024 vs 2025 | H32: 0.052542419 | I32: -0.0031448559 | O32: REM | P32: May-Jul 2024 | Q32: Nurses | R32: =VLOOKUP(O32,$K$12:$M$20,3,FALSE) -> 5517.8782 | S32: =VLOOKUP(O32,$A$12:$D$20,4,FALSE) -> 3728.7086 | T32: =VLOOKUP(O32,$F$12:$I$20,3,FALSE) -> 0.044696285 | U32: =VLOOKUP(O32,$F$12:$I$20,4,FALSE) -> 0.0090987785
O33: RGR | P33: May-Jul 2024 | Q33: Nurses | R33: =VLOOKUP(O33,$K$12:$M$20,3,FALSE) -> 1686.9346 | S33: =VLOOKUP(O33,$A$12:$D$20,4,FALSE) -> 1153.1382 | T33: =VLOOKUP(O33,$F$12:$I$20,3,FALSE) -> -0.001526081 | U33: =VLOOKUP(O33,$F$12:$I$20,4,FALSE) -> 0.0013247935
O34: RJC | P34: May-Jul 2024 | Q34: Nurses | R34: =VLOOKUP(O34,$K$12:$M$20,3,FALSE) -> 2118.0118 | S34: =VLOOKUP(O34,$A$12:$D$20,4,FALSE) -> 1488.2754 | T34: =VLOOKUP(O34,$F$12:$I$20,3,FALSE) -> 0.12220887 | U34: =VLOOKUP(O34,$F$12:$I$20,4,FALSE) -> 0.074737047
O35: RLT | P35: May-Jul 2024 | Q35: Nurses | R35: =VLOOKUP(O35,$K$12:$M$20,3,FALSE) -> 1168.5116 | S35: =VLOOKUP(O35,$A$12:$D$20,4,FALSE) -> 687.71201 | T35: =VLOOKUP(O35,$F$12:$I$20,3,FALSE) -> 0.13714284 | U35: =VLOOKUP(O35,$F$12:$I$20,4,FALSE) -> 0.08070623
O36: RTE | P36: May-Jul 2024 | Q36: Nurses | R36: =VLOOKUP(O36,$K$12:$M$20,3,FALSE) -> 3183.4919 | S36: =VLOOKUP(O36,$A$12:$D$20,4,FALSE) -> 2125.395 | T36: =VLOOKUP(O36,$F$12:$I$20,3,FALSE) -> 0.049401113 | U36: =VLOOKUP(O36,$F$12:$I$20,4,FALSE) -> 0.007315928
O37: Average* | P37: May-Jul 2024 | Q37: Nurses | R37: =VLOOKUP(O37,$K$12:$M$20,3,FALSE) -> 2397.5801 | S37: =VLOOKUP(O37,$A$12:$D$20,4,FALSE) -> 1612.0159 | T37: =VLOOKUP(O37,$F$12:$I$20,3,FALSE) -> 0.055081868 | U37: =VLOOKUP(O37,$F$12:$I$20,4,FALSE) -> 0.027386621
O38: National median | P38: May-Jul 2024 | Q38: Nurses | R38: =VLOOKUP(O38,$K$12:$M$20,3,FALSE) -> 2753.7411 | S38: =VLOOKUP(O38,$A$12:$D$20,4,FALSE) -> 1889.4665 | T38: =VLOOKUP(O38,$F$12:$I$20,3,FALSE) -> 0.052542419 | U38: =VLOOKUP(O38,$F$12:$I$20,4,FALSE) -> -0.0031448559
O39: Average* | P39: May-Jul 2025 | Q39: Nurses | R39: =VLOOKUP(O39,$K$12:$M$20,3,FALSE) -> 2397.5801 | S39: =VLOOKUP(O39,$A$22:$D$30,4,FALSE) -> 1656.1635 | T39: =VLOOKUP(O39,$F$12:$I$20,3,FALSE) -> 0.055081868 | U39: =VLOOKUP(O39,$F$12:$I$20,4,FALSE) -> 0.027386621
O40: National median | P40: May-Jul 2025 | Q40: Nurses | R40: =VLOOKUP(O40,$K$12:$M$20,3,FALSE) -> 2753.7411 | S40: =VLOOKUP(O40,$A$22:$D$30,4,FALSE) -> 1883.5244 | T40: =VLOOKUP(O40,$F$12:$I$20,3,FALSE) -> 0.052542419 | U40: =VLOOKUP(O40,$F$12:$I$20,4,FALSE) -> -0.0031448559
O41: RBK | P41: May-Jul 2025 | Q41: Nurses | R41: =VLOOKUP(O41,$K$12:$M$20,3,FALSE) -> 1951.7675 | S41: =VLOOKUP(O41,$A$22:$D$30,4,FALSE) -> 1404.9934 | T41: =VLOOKUP(O41,$F$12:$I$20,3,FALSE) -> 0.02677606 | U41: =VLOOKUP(O41,$F$12:$I$20,4,FALSE) -> 0.037321475
...

Sheet Figure 6
A1: org_code | B1: pre_pathway_1 | C1: pre_pathway_2 | D1: pre_pathway_3 | E1: post_pathway_1 | F1: post_pathway_2 | G1: post_pathway_3 | H1: All_Median_Pre_Pathway_1 | I1: All_Median_Post_Pathway_1 | J1: All_Median_Pre_Pathway_2 | K1: All_Median_Post_Pathway_2 | L1: All_Median_Pre_Pathway_3 | M1: All_Median_Post_Pathway_3 | N1: avgbest_Pre_pathway_1 | O1: avgbest_Post_pathway_1 | P1: avgbest_Pre_pathway_2 | Q1: avgbest_Post_pathway_2 | R1: avgbest_Pre_pathway_3 | S1: avgbest_Post_pathway_3
A2: RBK | B2: 163 | C2: 12.5 | D2: 40 | E2: 124.5 | F2: 13.5 | G2: 51.5 | H2: 178.5 | I2: 202 | J2: 63 | K2: 60.5 | L2: 30 | M2: 33 | N2: 290.14286 | O2: 250.85714 | P2: 63.285714 | Q2: 65.857143 | R2: 40.214286 | S2: 30.142857
A3: RCF | B3: 101 | C3: 43 | D3: 23 | E3: 108.5 | F3: 25 | G3: 26 | H3: 178.5 | I3: 202 | J3: 63 | K3: 60.5 | L3: 30 | M3: 33 | N3: 290.14286 | O3: 250.85714 | P3: 63.285714 | Q3: 65.857143 | R3: 40.214286 | S3: 30.142857
A4: REM | B4: 910.5 | C4: 73 | D4: 113.5 | E4: 907 | F4: 80 | G4: 83 | H4: 178.5 | I4: 202 | J4: 63 | K4: 60.5 | L4: 30 | M4: 33 | N4: 290.14286 | O4: 250.85714 | P4: 63.285714 | Q4: 65.857143 | R4: 40.214286 | S4: 30.142857
A5: RGR | B5: 107.5 | C5: 138 | D5: 27 | E5: 134.5 | F5: 142.5 | G5: 25.5 | H5: 178.5 | I5: 202 | J5: 63 | K5: 60.5 | L5: 30 | M5: 33 | N5: 290.14286 | O5: 250.85714 | P5: 63.285714 | Q5: 65.857143 | R5: 40.214286 | S5: 30.142857
A6: RJC | B6: 522.5 | C6: 28.5 | D6: 74.5 | E6: 121.5 | F6: 24 | G6: 15 | H6: 178.5 | I6: 202 | J6: 63 | K6: 60.5 | L6: 30 | M6: 33 | N6: 290.14286 | O6: 250.85714 | P6: 63.285714 | Q6: 65.857143 | R6: 40.214286 | S6: 30.142857
A7: RLT | B7: 65.5 | C7: 20 | D7: 3.5 | E7: 155.5 | F7: 49.5 | G7: 10 | H7: 178.5 | I7: 202 | J7: 63 | K7: 60.5 | L7: 30 | M7: 33 | N7: 290.14286 | O7: 250.85714 | P7: 63.285714 | Q7: 65.857143 | R7: 40.214286 | S7: 30.142857
A8: RTE | B8: 161 | C8: 128 | D8: 0 | E8: 204.5 | F8: 126.5 | G8: 0 | H8: 178.5 | I8: 202 | J8: 63 | K8: 60.5 | L8: 30 | M8: 33 | N8: 290.14286 | O8: 250.85714 | P8: 63.285714 | Q8: 65.857143 | R8: 40.214286 | S8: 30.142857

Sheet Figure 7
A1: org_code | B1: Pre_delay | C1: Post_delay | D1: All_Median_Pre_delay | E1: All_Median_Post_delay | F1: avgbest_Pre_delay | G1: avgbest_Post_delay
A2: RBK | B2: 5.5174489 | C2: 5.2653069 | D2: 6.2311558 | E2: 5.8301676 | F2: 7.2398899 | G2: 5.4847386
A3: RCF | B3: 7.871347 | C3: 5.5267966 | D3: 6.2311558 | E3: 5.8301676 | F3: 7.2398899 | G3: 5.4847386
A4: REM | B4: 9.9397269 | C4: 7.0055533 | D4: 6.2311558 | E4: 5.8301676 | F4: 7.2398899 | G4: 5.4847386
A5: RGR | B5: 6.9717756 | C5: 3.7366546 | D5: 6.2311558 | E5: 5.8301676 | F5: 7.2398899 | G5: 5.4847386
A6: RJC | B6: 4.0073025 | C6: 2.3499795 | D6: 6.2311558 | E6: 5.8301676 | F6: 7.2398899 | G6: 5.4847386
A7: RLT | B7: 5.5615442 | C7: 5.9405665 | D7: 6.2311558 | E7: 5.8301676 | F7: 7.2398899 | G7: 5.4847386
A8: RTE | B8: 10.810084 | C8: 8.5683127 | D8: 6.2311558 | E8: 5.8301676 | F8: 7.2398899 | G8: 5.4847386

Sheet Figure 7b
A1: month | B1: org_code | C1: average_delay_los_minus_0_day_delay
A2: Apr-24 | B2: National | C2: 6.1732535
A3: May-24 | B3: National | C3: 5.9697558
A4: Jun-24 | B4: National | C4: 5.9339607
A5: Jul-24 | B5: National | C5: 6.1635424
A6: Aug-24 | B6: National | C6: 6.0442756
A7: Sep-24 | B7: National | C7: 6.3068835
A8: Oct-24 | B8: National | C8: 6.0855723
A9: Nov-24 | B9: National | C9: 6.0615706
A10: Dec-24 | B10: National | C10: 6.0230541
A11: Jan-25 | B11: National | C11: 6.0566078
A12: Feb-25 | B12: National | C12: 6.0884952
A13: Mar-25 | B13: National | C13: 6.2134287
... A19: Sep-25 | B19: National | C19: 6.3030447

Sheet Most Improved Consistency
A1: month | B1: org_code | C1: patients_discharged_volume | D1: dd_bed_days | E1: no_delay_perc | F1: delay_perc | G1: no_delay_volume | H1: 1_day_delay_volume | I1: 2_3_day_delay_volume | J1: 4_6_day_delay_volume | K1: 7_13_day_delay_volume | L1: 14_20_day_delay_volume | M1: 21plus_day_delay_volume | N1: no_delay_percent | O1: 1_day_delay_perc | P1: 2_3_day_delay_perc | Q1: 4_6_day_delay_perc | R1: 7_13_day_delay_perc | S1: 14_20_day_delay_perc | T1: 21plus_day_delay_perc | U1: delayed_perc_1_day | V1: delayed_perc_2_3_days | W1: delayed_perc_4_6_days | X1: delayed_perc_7_13_days | Y1: delayed_perc_14_20_days | Z1: delayed_perc_21plus_days | AA1: 1_day_delay_beddays | AB1: 2_3_day_delay_beddays | AC1: 4_6_day_delay_beddays | AD1: 7_13_day_delay_beddays | AE1: 14_20_day_delay_beddays | AF1: 21plus_day_delay_beddays | AG1: average_delay_los_inc_0_day_delay | AH1: average_delay_los_minus_0_day_delay | AI1: total_delay_volume | AJ1: perc_patients_delayed | AK1: acute_beds | AL1: adult_acute_beds | AM1: occupied_beds | AN1: occupancy_rate | AO1: days_in_month | AP1: perc_bed_delays
A2: 45383 | B2: RCF | C2: 1250 | D2: 1659 | E2: 0.8272 | F2: 0.1728 | G2: 1034 | H2: 69 | I2: 46 | J2: 31 | K2: 32 | L2: 18 | M2: 20 | N2: 0.8272 | O2: 0.0552 | P2: 0.0368 | Q2: 0.0248 | R2: 0.0256 | S2: 0.0144 | T2: 0.016 | U2: 0.31944444 | V2: 0.21296296 | W2: 0.14351852 | X2: 0.14814815 | Y2: 0.083333333 | Z2: 0.092592593 | AA2: 69 | AB2: 111 | AC2: 164 | AD2: 311 | AE2: 305 | AF2: 699 | AG2: 1.3272 | AH2: 7.6805556 | AI2: 216 | AJ2: 17.28 | AK2: 354 | AL2: 338 | AM2: 336 | AN2: 0.95 | AO2: 30 | AP2: 16.360947
A3: 45383 | B3: RLT | C3: 1382 | D3: 3608 | E3: 0.61287988 | F3: 0.38712012 | G3: 847 | H3: 154 | I3: 123 | J3: 113 | K3: 80 | L3: 25 | M3: 40 | N3: 0.61287988 | O3: 0.11143271 | P3: 0.089001447 | Q3: 0.081765557 | R3: 0.05788712 | S3: 0.018089725 | T3: 0.02894356 | U3: 0.28785047 | V3: 0.22990654 | W3: 0.21121495 | X3: 0.14953271 | Y3: 0.046728972 | Z3: 0.074766355 | AA3: 154 | AB3: 304 | AC3: 545 | AD3: 736 | AE3: 423 | AF3: 1446 | AG3: 2.6107091 | AH3: 6.7439252 | AI3: 535 | AJ3: 38.712012 | AK3: 382 | AL3: 382 | AM3: 379 | AN3: 0.991 | AO3: 30 | AP3: 31.483421
A4: 45383 | B4: RTE | C4: 3524 | D4: 4022 | E4: 0.90266742 | F4: 0.097332577 | G4: 3181 | H4: 50 | I4: 51 | J4: 64 | K4: 82 | L4: 46 | M4: 50 | N4: 0.90266742 | O4: 0.014188422 | P4: 0.014472191 | Q4: 0.01816118 | R4: 0.023269012 | S4: 0.013053348 | T4: 0.014188422 | U4: 0.14577259 | V4: 0.14868805 | W4: 0.18658892 | X4: 0.23906706 | Y4: 0.13411079 | Z4: 0.14577259 | AA4: 50 | AB4: 132 | AC4: 323 | AD4: 791 | AE4: 739 | AF4: 1987 | AG4: 1.1413167 | AH4: 11.725948 | AI4: 343 | AJ4: 9.7332577 | AK4: 873 | AL4: 813 | AM4: 794 | AN4: 0.909 | AO4: 30 | AP4: 16.490365
A5: 45383 | B5: REM | C5: 4429 | D5: 5457 | E5: 0.84262813 | F5: 0.15737187 | G5: 3732 | H5: 203 | I5: 142 | J5: 125 | K5: 123 | L5: 44 | M5: 60 | N5: 0.84262813 | O5: 0.045834274 | P5: 0.032061413 | Q5: 0.028223075 | R5: 0.027771506 | S5: 0.0099345225 | T5: 0.013547076 | U5: 0.29124821 | V5: 0.20373027 | W5: 0.17934003 | X5: 0.17647059 | Y5: 0.06312769 | Z5: 0.086083214 | AA5: 203 | AB5: 335 | AC5: 612 | AD5: 1084 | AE5: 725 | AF5: 2498 | AG5: 1.2321066 | AH5: 7.8292683 | AI5: 697 | AJ5: 15.737187 | AK5: 1620 | AL5: 1620 | AM5: 1513 | AN5: 0.933 | AO5: 30 | AP5: 11.228395
A6: 45383 | B6: RJC | C6: 1660 | D6: 1248 | E6: 0.81807229 | F6: 0.18192771 | G6: 1358 | H6: 131 | I6: 83 | J6: 40 | K6: 28 | L6: 12 | M6: 8 | N6: 0.81807229 | O6: 0.078915663 | P6: 0.05 | Q6: 0.024096386 | R6: 0.01686747 | S6: 0.0072289157 | T6: 0.0048192771 | U6: 0.43377483 | V6: 0.27483444 | W6: 0.13245033 | X6: 0.092715232 | Y6: 0.039735099 | Z6: 0.026490066 | AA6: 131 | AB6: 194 | AC6: 196 | AD6: 263 | AE6: 197 | AF6: 267 | AG6: 0.75180723 | AH6: 4.1324503 | AI6: 302 | AJ6: 18.192771 | AK6: 400 | AL6: 383 | AM6: 377 | AN6: 0.944 | AO6: 30 | AP6: 10.861619
A7: 45383 | B7: RGR | C7: 1916 | D7: 1415 | E7: 0.85020877 | F7: 0.14979123 | G7: 1629 | H7: 106 | I7: 60 | J7: 55 | K7: 47 | L7: 9 | M7: 10 | N7: 0.85020877 | O7: 0.055323591 | P7: 0.03131524 | Q7: 0.028705637 | R7: 0.024530271 | S7: 0.004697286 | T7: 0.0052192067 | U7: 0.36933798 | V7: 0.20905923 | W7: 0.19163763 | X7: 0.16376307 | Y7: 0.031358885 | Z7: 0.034843206 | AA7: 106 | AB7: 144 | AC7: 271 | AD7: 423 | AE7: 149 | AF7: 322 | AG7: 0.73851775 | AH7: 4.9303136 | AI7: 287 | AJ7: 14.979123 | AK7: 483 | AL7: 468 | AM7: 452 | AN7: 0.936 | AO7: 30 | AP7: 10.078348
A8: 45383 | B8: RBK | C8: 0 | D8: 0 | G8: 0 | H8: 0 | I8: 0 | J8: 0 | K8: 0 | L8: 0 | M8: 0 | AI8: 0 | AJ8: #NUM! | AK8: 537 | AL8: 489 | AM8: 486 | AN8: 0.905 | AO8: 30 | AP8: 0
A9: 45413 | B9: RCF | C9: 1339 | D9: 1535 | E9: 0.82001494 | F9: 0.17998506 | G9: 1098 | H9: 60 | I9: 59 | J9: 44 | K9: 49 | L9: 15 | M9: 14 | N9: 0.82001494 | O9: 0.044809559 | P9: 0.044062733 | Q9: 0.032860344 | R9: 0.036594473 | S9: 0.01120239 | T9: 0.010455564 | U9: 0.24896266 | V9: 0.24481328 | W9: 0.18257261 | X9: 0.2033195 | Y9: 0.062240664 | Z9: 0.058091286 | AA9: 60 | AB9: 136 | AC9: 220 | AD9: 461 | AE9: 235 | AF9: 423 | AG9: 1.1463779 | AH9: 6.3692946 | AI9: 241 | AJ9: 17.998506 | AK9: 356 | AL9: 341 | AM9: 342 | AN9: 0.962 | AO9: 31 | AP9: 14.520859
A10: 45413 | B10: RLT | C10: 1427 | D10: 3085 | E10: 0.63980378 | F10: 0.36019622 | G10: 913 | H10: 148 | I10: 122 | J10: 105 | K10: 81 | L10: 35 | M10: 23 | N10: 0.63980378 | O10: 0.10371409 | P10: 0.085494043 | Q10: 0.073580939 | R10: 0.056762439 | S10: 0.02452698 | T10: 0.01611773 | U10: 0.28793774 | V10: 0.23735409 | W10: 0.20428016 | X10: 0.15758755 | Y10: 0.068093385 | Z10: 0.044747082 | AA10: 148 | AB10: 284 | AC10: 511 | AD10: 744 | AE10: 564 | AF10: 834 | AG10: 2.1618781 | AH10: 6.0019455 | AI10: 514 | AJ10: 36.019622 | AK10: 380 | AL10: 380 | AM10: 376 | AN10: 0.99 | AO10: 31 | AP10: 26.188455
A11: 45413 | B11: RTE | C11: 3690 | D11: 4631 | E11: 0.90379404 | F11: 0.096205962 | G11: 3335 | H11: 55 | I11: 54 | J11: 55 | K11: 91 | L11: 34 | M11: 66 | N11: 0.90379404 | O11: 0.014905149 | P11: 0.014634146 | Q11: 0.014905149 | R11: 0.024661247 | S11: 0.0092140921 | T11: 0.017886179 | U11: 0.15492958 | V11: 0.15211268 | W11: 0.15492958 | X11: 0.25633803 | Y11: 0.095774648 | Z11: 0.18591549 | AA11: 55 | AB11: 127 | AC11: 281 | AD11: 854 | AE11: 563 | AF11: 2751 | AG11: 1.2550136 | AH11: 13.04507 | AI11: 355 | AJ11: 9.6205962 | AK11: 873 | AL11: 813 | AM11: 783 | AN11: 0.896 | AO11: 31 | AP11: 18.374797
A12: 45413 | B12: REM | C12: 4710 | D12: 6576 | E12: 0.83269639 | F12: 0.16730361 | G12: 3922 | H12: 245 | I12: 174 | J12: 111 | K12: 130 | L12: 47 | M12: 81 | N12: 0.83269639 | O12: 0.052016985 | P12: 0.036942675 | Q12: 0.023566879 | R12: 0.027600849 | S12: 0.0099787686 | T12: 0.017197452 | U12: 0.31091371 | V12: 0.22081218 | W12: 0.14086294 | X12: 0.16497462 | Y12: 0.05964467 | Z12: 0.10279188 | AA12: 245 | AB12: 411 | AC12: 541 | AD12: 1193 | AE12: 766 | AF12: 3420 | AG12: 1.3961783 | AH12: 8.3451777 | AI12: 788 | AJ12: 16.730361 | AK12: 1622 | AL12: 1622 | AM12: 1519 | AN12: 0.937 | AO12: 31 | AP12: 13.078239
A13: 45413 | B13: RJC | C13: 1716 | D13: 1507 | E13: 0.81293706 | F13: 0.18706294 | G13: 1395 | H13: 136 | I13: 76 | J13: 44 | K13: 32 | L13: 19 | M13: 14 | N13: 0.81293706 | O13: 0.079254079 | P13: 0.044289044 | Q13: 0.025641026 | R13: 0.018648019 | S13: 0.011072261 | T13: 0.0081585082 | U13: 0.42367601 | V13: 0.23676012 | W13: 0.13707165 | X13: 0.099688474 | Y13: 0.059190031 | Z13: 0.043613707 | AA13: 136 | AB13: 176 | AC13: 211 | AD13: 259 | AE13: 319 | AF13: 406 | AG13: 0.87820513 | AH13: 4.694704 | AI13: 321 | AJ13: 18.706294 | AK13: 403 | AL13: 386 | AM13: 387 | AN13: 0.96 | AO13: 31 | AP13: 12.594016
A14: 45413 | B14: RGR | C14: 2017 | D14: 1520 | E14: 0.83688647 | F14: 0.16311353 | G14: 1688 | H14: 128 | I14: 93 | J14: 40 | K14: 52 | L14: 5 | M14: 11 | N14: 0.83688647 | O14: 0.063460585 | P14: 0.046108081 | Q14: 0.019831433 | R14: 0.025780863 | S14: 0.0024789291 | T14: 0.005453644 | U14: 0.38905775 | V14: 0.28267477 | W14: 0.12158055 | X14: 0.15805471 | Y14: 0.015197568 | Z14: 0.03343465 | AA14: 128 | AB14: 228 | AC14: 203 | AD14: 476 | AE14: 84 | AF14: 401 | AG14: 0.75359445 | AH14: 4.6200608 | AI14: 329 | AJ14: 16.311353 | AK14: 467 | AL14: 452 | AM14: 435 | AN14: 0.93 | AO14: 31 | AP14: 10.847845
A15: 45413 | B15: RBK | C15: 0 | D15: 0 | G15: 0 | H15: 0 | I15: 0 | J15: 0 | K15: 0 | L15: 0 | M15: 0 | AI15: 0 | AJ15: #NUM! | AK15: 535 | AL15: 488 | AM15: 484 | AN15: 0.904 | AO15: 31 | AP15: 0
A16: 45444 | B16: RCF | C16: 1207 | D16: 1346 | E16: 0.81441591 | F16: 0.18558409 | G16: 983 | H16: 66 | I16: 46 | J16: 36 | K16: 49 | L16: 20 | M16: 7 | N16: 0.81441591 | O16: 0.054681027 | P16: 0.038111019 | Q16: 0.029826015 | R16: 0.04059652 | S16: 0.016570008 | T16: 0.0057995029 | U16: 0.29464286 | V16: 0.20535714 | W16: 0.16071429 | X16: 0.21875 | Y16: 0.089285714 | Z16: 0.03125 | AA16: 66 | AB16: 108 | AC16: 181 | AD16: 446 | AE16: 322 | AF16: 223 | AG16: 1.1151616 | AH16: 6.0089286 | AI16: 224 | AJ16: 18.558409 | AK16: 354 | AL16: 339 | AM16: 343 | AN16: 0.968 | AO16: 30 | AP16: 13.235005
A17: 45444 | B17: RLT | C17: 1387 | D17: 2983 | E17: 0.62941601 | F17: 0.37058399 | G17: 873 | H17: 130 | I17: 145 | J17: 119 | K17: 72 | L17: 25 | M17: 23 | N17: 0.62941601 | O17: 0.093727469 | P17: 0.10454218 | Q17: 0.085796683 | R17: 0.051910598 | S17: 0.018024513 | T17: 0.016582552 | U17: 0.25291829 | V17: 0.28210117 | W17: 0.23151751 | X17: 0.14007782 | Y17: 0.048638132 | Z17: 0.044747082 | AA17: 130 | AB17: 361 | AC17: 586 | AD17: 655 | AE17: 412 | AF17: 839 | AG17: 2.1506849 | AH17: 5.8035019 | AI17: 514 | AJ17: 37.058399 | AK17: 381 | AL17: 381 | AM17: 377 | AN17: 0.99 | AO17: 30 | AP17: 26.097988
A18: 45444 | B18: RTE | C18: 3459 | D18: 3965 | E18: 0.89939289 | F18: 0.10060711 | G18: 3111 | H18: 51 | I18: 52 | J18: 62 | K18: 84 | L18: 46 | M18: 53 | N18: 0.89939289 | O18: 0.014744146 | P18: 0.015033247 | Q18: 0.017924256 | R18: 0.024284475 | S18: 0.013298641 | T18: 0.015322347 | U18: 0.14655172 | V18: 0.14942529 | W18: 0.17816092 | X18: 0.24137931 | Y18: 0.13218391 | Z18: 0.15229885 | AA18: 51 | AB18: 123 | AC18: 307 | AD18: 813 | AE18: 743 | AF18: 1928 | AG18: 1.1462851 | AH18: 11.393678 | AI18: 348 | AJ18: 10.060711 | AK18: 869 | AL18: 809 | AM18: 781 | AN18: 0.899 | AO18: 30 | AP18: 16.337042
A19: 45444 | B19: REM | C19: 4448 | D19: 7046 | E19: 0.87027878 | F19: 0.12972122 | G19: 3871 | H19: 129 | I19: 105 | J19: 83 | K19: 125 | L19: 45 | M19: 90 | N19: 0.87027878 | O19: 0.029001799 | P19: 0.023606115 | Q19: 0.018660072 | R19: 0.028102518 | S19: 0.010116906 | T19: 0.020233813 | U19: 0.22357019 | V19: 0.18197574 | W19: 0.14384749 | X19: 0.21663778 | Y19: 0.077989601 | Z19: 0.1559792 | AA19: 129 | AB19: 257 | AC19: 418 | AD19: 1159 | AE19: 742 | AF19: 4341 | AG19: 1.5840827 | AH19: 12.211438 | AI19: 577 | AJ19: 12.972122 | AK19: 1612 | AL19: 1612 | AM19: 1520 | AN19: 0.943 | AO19: 30 | AP19: 14.569892
A20: 45444 | B20: RJC | C20: 1632 | D20: 1200 | E20: 0.82169118 | F20: 0.17830882 | G20: 1341 | H20: 112 | I20: 82 | J20: 44 | K20: 38 | L20: 10 | M20: 5 | N20: 0.82169118 | O20: 0.068627451 | P20: 0.050245098 | Q20: 0.026960784 | R20: 0.023284314 | S20: 0.006127451 | T20: 0.0030637255 | U20: 0.38487973 | V20: 0.28178694 | W20: 0.15120275 | X20: 0.13058419 | Y20: 0.034364261 | Z20: 0.017182131 | AA20: 112 | AB20: 194 | AC20: 217 | AD20: 340 | AE20: 179 | AF20: 158 | AG20: 0.73529412 | AH20: 4.1237113 | AI20: 291 | AJ20: 17.830882 | AK20: 404 | AL20: 387 | AM20: 387 | AN20: 0.959 | AO20: 30 | AP20: 10.335917
A21: 45444 | B21: RBK | C21: 1835 | D21: 1020 | E21: 0.88501362 | F21: 0.11498638 | G21: 1624 | H21: 50 | I21: 51 | J21: 58 | K21: 40 | L21: 9 | M21: 3 | N21: 0.88501362 | O21: 0.027247956 | P21: 0.027792916 | Q21: 0.031607629 | R21: 0.021798365 | S21: 0.0049046322 | T21: 0.0016348774 | U21: 0.23696682 | V21: 0.24170616 | W21: 0.27488152 | X21: 0.18957346 | Y21: 0.042654028 | Z21: 0.014218009 | AA21: 50 | AB21: 130 | AC21: 274 | AD21: 348 | AE21: 143 | AF21: 75 | AG21: 0.55585831 | AH21: 4.8341232 | AI21: 211 | AJ21: 11.498638 | AK21: 533 | AL21: 488 | AM21: 493 | AN21: 0.925 | AO21: 30 | AP21: 6.9672131
A22: 45444 | B22: RGR | C22: 1810 | D22: 1113 | E22: 0.84972376 | F22: 0.15027624 | G22: 1538 | H22: 114 | I22: 75 | J22: 36 | K22: 32 | L22: 9 | M22: 6 | N22: 0.84972376 | O22: 0.062983425 | P22: 0.041436464 | Q22: 0.019889503 | R22: 0.017679558 | S22: 0.0049723757 | T22: 0.0033149171 | U22: 0.41911765 | V22: 0.27573529 | W22: 0.13235294 | X22: 0.11764706 | Y22: 0.033088235 | Z22: 0.022058824 | AA22: 114 | AB22: 178 | AC22: 170 | AD22: 287 | AE22: 153 | AF22: 211 | AG22: 0.61491713 | AH22: 4.0919118 | AI22: 272 | AJ22: 15.027624 | AK22: 447 | AL22: 432 | AM22: 415 | AN22: 0.928 | AO22: 30 | AP22: 8.587963
A23: 45474 | B23: RCF | C23: 1278 | D23: 1901 | E23: 0.81064163 | F23: 0.18935837 | G23: 1036 | H23: 43 | I23: 51 | J23: 46 | K23: 57 | L23: 32 | M23: 13 | N23: 0.81064163 | O23: 0.033646322 | P23: 0.039906103 | Q23: 0.03599374 | R23: 0.044600939 | S23: 0.025039124 | T23: 0.010172144 | U23: 0.17768595 | V23: 0.2107438 | W23: 0.19008264 | X23: 0.23553719 | Y23: 0.1322314 | Z23: 0.053719008 | AA23: 43 | AB23: 129 | AC23: 225 | AD23: 515 | AE23: 508 | AF23: 481 | AG23: 1.4874804 | AH23: 7.8553719 | AI23: 242 | AJ23: 18.935837 | AK23: 350 | AL23: 335 | AM23: 331 | AN23: 0.946 | AO23: 31 | AP23: 18.305248
A24: 45474 | B24: RLT | C24: 1442 | D24: 3065 | E24: 0.61581137 | F24: 0.38418863 | G24: 888 | H24: 148 | I24: 157 | J24: 111 | K24: 82 | L24: 28 | M24: 28 | N24: 0.61581137 | O24: 0.10263523 | P24: 0.10887656 | Q24: 0.076976422 | R24: 0.056865465 | S24: 0.019417476 | T24: 0.019417476 | U24: 0.26714801 | V24: 0.2833935 | W24: 0.20036101 | X24: 0.14801444 | Y24: 0.050541516 | Z24: 0.050541516 | AA24: 148 | AB24: 382 | AC24: 537 | AD24: 734 | AE24: 455 | AF24: 809 | AG24: 2.1255201 | AH24: 5.532491 | AI24: 554 | AJ24: 38.418863 | AK24: 361 | AL24: 361 | AM24: 353 | AN24: 0.98 | AO24: 31 | AP24: 27.38808
A25: 45474 | B25: RTE | C25: 3798 | D25: 4518 | E25: 0.90047393 | F25: 0.099526066 | G25: 3420 | H25: 56 | I25: 58 | J25: 55 | K25: 103 | L25: 43 | M25: 63 | N25: 0.90047393 | O25: 0.014744602 | P25: 0.015271195 | Q25: 0.014481306 | R25: 0.027119537 | S25: 0.011321748 | T25: 0.016587678 | U25: 0.14814815 | V25: 0.15343915 | W25: 0.14550265 | X25: 0.27248677 | Y25: 0.11375661 | Z25: 0.16666667 | AA25: 56 | AB25: 144 | AC25: 280 | AD25: 946 | AE25: 705 | AF25: 2387 | AG25: 1.1895735 | AH25: 11.952381 | AI25: 378 | AJ25: 9.9526066 | AK25: 862 | AL25: 802 | AM25: 760 | AN25: 0.882 | AO25: 31 | AP25: 18.172311
A26: 45474 | B26: REM | C26: 4663 | D26: 6809 | E26: 0.85502895 | F26: 0.14497105 | G26: 3987 | H26: 200 | I26: 137 | J26: 106 | K26: 116 | L26: 37 | M26: 80 | N26: 0.85502895 | O26: 0.042890843 | P26: 0.029380227 | Q26: 0.022732147 | R26: 0.024876689 | S26: 0.0079348059 | T26: 0.017156337 | U26: 0.29585799 | V26: 0.20266272 | W26: 0.15680473 | X26: 0.17159763 | Y26: 0.054733728 | Z26: 0.1183432 | AA26: 200 | AB26: 327 | AC26: 505 | AD26: 1074 | AE26: 618 | AF26: 4085 | AG26: 1.4602187 | AH26: 10.072485 | AI26: 676 | AJ26: 14.497105 | AK26: 1607 | AL26: 1607 | AM26: 1499 | AN26: 0.933 | AO26: 31 | AP26: 13.668025
A27: 45474 | B27: RJC | C27: 1730 | D27: 1395 | E27: 0.80693642 | F27: 0.19306358 | G27: 1396 | H27: 147 | I27: 89 | J27: 40 | K27: 34 | L27: 13 | M27: 11 | N27: 0.80693642 | O27: 0.084971098 | P27: 0.051445087 | Q27: 0.023121387 | R27: 0.019653179 | S27: 0.0075144509 | T27: 0.0063583815 | U27: 0.44011976 | V27: 0.26646707 | W27: 0.11976048 | X27: 0.10179641 | Y27: 0.038922156 | Z27: 0.032934132 | AA27: 147 | AB27: 204 | AC27: 191 | AD27: 303 | AE27: 218 | AF27: 332 | AG27: 0.80635838 | AH27: 4.1766467 | AI27: 334 | AJ27: 19.306358 | AK27: 408 | AL27: 391 | AM27: 376 | AN27: 0.92 | AO27: 31 | AP27: 11.508951
... A127: 45901 | B127: RGR | C127: 1945 | D127: 1190 | E127: 0.84575835 | F127: 0.15424165 | G127: 1645 | H127: 116 | I127: 90 | J127: 42 | K127: 35 | L127: 11 | M127: 6 | N127: 0.84575835 | O127: 0.059640103 | P127: 0.046272494 | Q127: 0.02159383 | R127: 0.017994859 | S127: 0.005655527 | T127: 0.0030848329 | U127: 0.38666667 | V127: 0.3 | W127: 0.14 | X127: 0.11666667 | Y127: 0.036666667 | Z127: 0.02 | AA127: 116 | AB127: 219 | AC127: 200 | AD127: 311 | AE127: 176 | AF127: 168 | AG127: 0.61182519 | AH127: 3.9666667 | AI127: 300 | AJ127: 15.424165 | AK127: 460 | AL127: 445 | AM127: 431 | AN127: 0.939 | AO127: 30 | AP127: 8.9138577

Sheet All trusts staffing
A1: month | B1: org_code | C1: doctors | D1: nurses
A2: May-24 | B2: RJ1 | C2: 3058.6377 | D2: 6288.1928
A3: May-24 | B3: RJZ | C3: 2502.4297 | D3: 4435.0992
A4: May-24 | B4: RJ2 | C4: 1011.2317 | D4: 2154.6178
A5: May-24 | B5: RF4 | C5: 1275.9758 | D5: 2228.844
A6: May-24 | B6: R1H | C6: 2974.6071 | D6: 5044.648
A7: May-24 | B7: RQX | C7: 559.69245 | D7: 1145.8916
A8: May-24 | B8: RAP | C8: 623.70639 | D8: 1353.1324
A9: May-24 | B9: RAL | C9: 1784.936 | D9: 3040.4677
A10: May-24 | B10: RRV | C10: 1777.4237 | D10: 3102.5304
A11: May-24 | B11: RKE | C11: 551.68104 | D11: 1125.5531
A12: May-24 | B12: RQM | C12: 1369.5601 | D12: 2131.0864
A13: May-24 | B13: RAS | C13: 497.1678 | D13: 916.7007
... A718: Jul-25 | B718: RXF | C718: 1010.3964 | D718: 1967.7665
